<mujoco model="000_NABI">
    <compiler angle="radian" coordinate="local" inertiafromgeom="true" meshdir="meshes/" />
    <!--<option timestep="0.02" iterations="50" solver="Newton" jacobian="auto" cone="elliptic" tolerance="1e-10" impratio ="1" />-->
    <!--impratio ="1"  o_solref="0.02 1.2"-->
    <option gravity="0 0 -9.81" integrator="RK4" timestep="0.01" solver="Newton" jacobian="auto" iterations="50" tolerance="1e-10" cone="elliptic" impratio="1"/>
    <option>
        <flag override="enable" />
        <!--warmstart="enable" -->
    </option>

    <size njmax="500" nconmax="100" nstack="300000"/>

    <default>
        <joint limited="true"/>
        <!--<joint armature="0.01" limited="true"/>-->
        <!--<geom solimp="0.9 0.9 0.1" density="1" conaffinity="1" condim="3" friction="1 .5 .01" margin="0.01" rgba="0.8 0.6 0.4 1"/>-->
        <geom solimp="0.9 0.9 0.1" conaffinity="0" condim="3" density="20" friction="1 1 1" margin="0.01" rgba="0.8 0.6 0.4 1" />
        <!--d:impedance, b*xdot:damping, k*x:stiffness-->
    </default>

    <asset>
        <texture builtin="gradient" height="128" rgb1="1 1 1" rgb2="0 0 0" type="skybox" width="128"/>
        <texture builtin="flat" height="1278" mark="cross" markrgb="1 1 1" name="texgeom" random="0.01" rgb1="0.8 0.6 0.4" rgb2="0.8 0.6 0.4" type="cube" width="127"/>
        <texture builtin="checker" height="512" name="texplane" rgb1="0 0 0" rgb2="0.8 0.8 0.8" type="2d" width="512"/>
        <!--<texture name="groundplane" type="2d" builtin="checker" rgb1=".7 .7 .75" rgb2=".9 .9 .95" width="500" height="500" mark="edge" markrgb=".1 .1 .1"/>-->
        <material name="MatPlane" reflectance="0.5" shininess="1" specular="1" texrepeat="60 60" texture="texplane"/>
        <material name="geom" texture="texgeom" texuniform="true"/>
        <!--<material name="MatGnd" texture="groundplane"  texrepeat="5 5" specular=".5" shininess=".01" reflectance="0.1"/>-->
        <mesh name="base_link" file="base_link.STL" />
        <mesh name="Right_Femur" file="Right_Femur.STL" />
        <mesh name="Right_Tibia" file="Right_Tibia.STL" />
        <mesh name="Right_Foot" file="Right_Foot.STL" />
        <mesh name="Left_Femur" file="Left_Femur.STL" />
        <mesh name="Left_Tibia" file="Left_Tibia.STL" />
        <mesh name="Left_Foot" file="Left_Foot.STL" />
    </asset>

    <worldbody>
        <light cutoff="100" diffuse="1 1 1" dir="-0 0 -1.3" directional="true" exponent="1" pos="0 0 1.3" specular=".1 .1 .1"/>
        <geom conaffinity="1" condim="3" material="MatPlane" friction="1 1 1" name="floor" pos="0 0 0" rgba="0.8 0.9 0.8 1" size="40 40 40" type="plane"/>
        <!--<geom solimp="1 0.1 0.1" density="3000" mass="3000"/>-->
        <!--<geom name="ground" pos="0 0 0" size="2 2 1" material="MatGnd" type="plane"/>-->
        <!--0.857526, 0.84589, xyaxes="1 0 0 0 0 1" -->
        <!--pi = 3.1415927, pi/3 = 1.0472, pi/6 = 0.5236, pi/4 = 0.7854, pi/2 = 1.5708, 75degree = 1.3090, 1degree=0.0174 ,-:RH, +:RK, +:LH, -:LK-->
        <!--0.5degree=0.0087, 20degree = 0.3491-->
        <!--For JUMP: RH - range="-1.5708 0", RK - range="0 0.7854", LH - range="0 1.5708", LK - "-0.7854 0"-->
                <body name="base_link" pos="0 0 0.84589">
            <camera name="track" mode="trackcom" pos="0 -3 0.3" xyaxes="1 0 0 0 0 1"  />
            <inertial pos="0.00027583 -4.69e-05 -0.00942057" quat="0.707017 0.707156 -0.00527789 0.00537538" mass="1.40983" diaginertia="0.00475204 0.00467702 0.00288471" />
            <geom type="mesh" rgba="0.752941 0.752941 0.752941 1" mesh="base_link" friction="1 1 1"/>
            <joint armature="0" damping="0" limited="false" margin="0.01" name="root" pos="0 0 0" type="free" stiffness="5"/>

            <body name="Right_Femur" pos="0 -0.05 -0.0558" quat="0.707105 0 0.707108 0">
                <inertial pos="0.30242 -1.9612e-05 3.37e-06" quat="0.50001 0.500019 0.49999 0.499981" mass="0.49995" diaginertia="0.0080336 0.007724 0.00040953" />
                <joint name="Right_Hip_Joint" pos="0 0 0" axis="0 0 1" range="-1.5708 0" type="hinge" armature="0.01" />
                <joint name="Right_Hip_Joint_Backlash" pos="0 0 0" axis="0 0 1" limited="true" range="-0.0087 0.0087" type="hinge"/>
                <geom type="mesh" rgba="0.75294 0.75294 0.75294 1" mesh="Right_Femur"/>

                <body name="Right_Tibia" pos="0.39152 0 0">
                    <inertial pos="0.21616 0 0" quat="0.500018 0.500018 0.499982 0.499982" mass="0.23236" diaginertia="0.0044393 0.0043773 0.00010871" />
                    <joint name="Right_Knee_Joint" pos="0 0 0" axis="0 0 1" range="0 0.7854" type="hinge" armature="0.01"/>
                    <joint name="Right_Knee_Joint_Backlash" pos="0 0 0" axis="0 0 1" limited="true" range="-0.0087 0.0087" type="hinge"/>
                    <geom type="mesh" rgba="0.75294 0.75294 0.75294 1" mesh="Right_Tibia"/>

                    <body name="Right_Foot" pos="0.39857 0 0">
                        <inertial pos="-0.011636 0 0" mass="0.10898" diaginertia="0.00089938 0.00089221 1.0016e-05" />
                        <geom type="mesh" rgba="0.75294 0.75294 0.75294 1" mesh="Right_Foot" friction="1 1 1" />
                        <joint name="Right_Foot_Spring" pos = "0 0 0" axis="1 0 0" type = "slide" stiffness="5" range="-0.01 0.01"/>

                    </body>
                </body>
            </body>

            <body name="Left_Femur" pos="0 0.05 -0.0558" quat="0.707105 0 0.707108 0">
                <inertial pos="0.30242 -1.9612e-05 3.37e-06" quat="0.50001 0.500018 0.49999 0.499982" mass="0.49995" diaginertia="0.00547898 0.00547898 0.00547898" />
                <joint name="Left_Hip_Joint" pos="0 0 0" axis="0 0 1" range="0 1.5708" type="hinge" armature="0.01"/>
                <joint name="Left_Hip_Joint_Backlash" pos="0 0 0" axis="0 0 1" limited="true" range="-0.0087 0.0087" type="hinge"/>
                <geom type="mesh" rgba="0.75294 0.75294 0.75294 1" mesh="Left_Femur"/>

                <body name="Left_Tibia" pos="0.39152 0 0">
                    <inertial pos="0.21616 0 0" quat="0.500018 0.500018 0.499982 0.499982" mass="0.23236" diaginertia="0.0044393 0.0043773 0.00010871" />
                    <joint name="Left_Knee_Joint" pos="0 0 0" axis="0 0 1" range="-0.7854 0" type="hinge" armature="0.01"/>
                    <joint name="Left_Knee_Joint_Backlash" pos="0 0 0" axis="0 0 1" limited="true" range="-0.0087 0.0087" type="hinge"/>
                    <geom type="mesh" rgba="0.75294 0.75294 0.75294 1" mesh="Left_Tibia"/>

                    <body name="Left_Foot" pos="0.39857 0 0">
                        <inertial pos="-0.011636 0 0" mass="0.10898" diaginertia="0.00089938 0.00089221 1.0016e-05" />
                        <geom type="mesh" rgba="0.75294 0.75294 0.75294 1" mesh="Left_Foot" friction="1 1 1"/>
                        <joint name="Left_Foot_Spring" pos = "0 0 0" axis="1 0 0" type = "slide" stiffness="5" range="-0.01 0.01"/>
                    </body>
                </body>
            </body>
        </body>
    </worldbody>
    <actuator>
        <general ctrllimited="true" ctrlrange="-1 1" forcelimited="true" forcerange="-20 20" joint="Right_Hip_Joint" gear="1" gaintype="fixed" gainprm="5" biastype="affine" biasprm="0 0 -2"/>
        <general ctrllimited="true" ctrlrange="-1 1" forcelimited="true" forcerange="-20 20" joint="Right_Knee_Joint" gear="1" gaintype="fixed" gainprm="5" biastype="affine" biasprm="0 0 -2"/>
        <general ctrllimited="true" ctrlrange="-1 1" forcelimited="true" forcerange="-20 20" joint="Left_Hip_Joint" gear="1" gaintype="fixed" gainprm="5" biastype="affine" biasprm="0 0 -2"/>
        <general ctrllimited="true" ctrlrange="-1 1" forcelimited="true" forcerange="-20 20" joint="Left_Knee_Joint" gear="1" gaintype="fixed" gainprm="5" biastype="affine" biasprm="0 0 -2"/>

        <general ctrllimited="true" ctrlrange="-1 1" forcelimited="true" forcerange="-0.1 0.1" joint="Right_Hip_Joint_Backlash" gear="1" gaintype="fixed" gainprm="0.5" biastype="affine" biasprm="0 0 -0.005"/>
        <general ctrllimited="true" ctrlrange="-1 1" forcelimited="true" forcerange="-0.1 0.1" joint="Right_Knee_Joint_Backlash" gear="1" gaintype="fixed" gainprm="0.5" biastype="affine" biasprm="0 0 -0.005"/>
        <general ctrllimited="true" ctrlrange="-1 1" forcelimited="true" forcerange="-0.1 0.1" joint="Left_Hip_Joint_Backlash" gear="1" gaintype="fixed" gainprm="0.5" biastype="affine" biasprm="0 0 -0.005"/>
        <general ctrllimited="true" ctrlrange="-1 1" forcelimited="true" forcerange="-0.1 0.1" joint="Left_Knee_Joint_Backlash" gear="1" gaintype="fixed" gainprm="0.5" biastype="affine" biasprm="0 0 -0.005"/>

        <general ctrllimited="true" ctrlrange="-1 1" forcelimited="true" forcerange="-5 5" joint="Right_Foot_Spring" gear="1" gaintype="fixed" gainprm="5" biastype="affine" biasprm="0 0 -2"/>
        <general ctrllimited="true" ctrlrange="-1 1" forcelimited="true" forcerange="-5 5" joint="Left_Foot_Spring" gear="1" gaintype="fixed" gainprm="5" biastype="affine" biasprm="0 0 -2"/>


    </actuator>
    <contact>
        <exclude body1="base_link" body2="Right_Femur" />
        <exclude body1="base_link" body2="Right_Tibia" />
        <exclude body1="base_link" body2="Left_Femur" />
        <exclude body1="base_link" body2="Left_Tibia" />
        <exclude body1="Right_Femur" body2="Left_Femur" />
        <exclude body1="Right_Femur" body2="Right_Tibia" />
        <exclude body1="Right_Femur" body2="Left_Tibia" />
        <exclude body1="Left_Femur" body2="Left_Tibia" />
        <exclude body1="Left_Femur" body2="Right_Tibia" />
    </contact>
</mujoco>


<!--<mesh name="base_link" file="base_link.STL" />-->
<!--<mesh name="Right_Femur" file="Right_Femur.STL" />-->
<!--<mesh name="Right_Tibia" file="Right_Tibia.STL" />-->
<!--<mesh name="Right_Foot" file="Right_Foot.STL" />-->
<!--<mesh name="Left_Femur" file="Left_Femur.STL" />-->
<!--<mesh name="Left_Tibia" file="Left_Tibia.STL" />-->
<!--<mesh name="Left_Foot" file="Left_Foot.STL" />-->

<!--FRICTION, ACTUATOR, MATERIAL of FOOT, DAMPING and STIFFNESS of FOOT or ENV-->
<!--1. MX-106 - Gear Ration = 225:1, G
<general ctrllimited="true" ctrlrange="-1 1" forcelimited="true" forcerange="-20.0 20.0" joint="Left_Knee_Joint" gear="1" gaintype="fixed" gainprm="62.8" biastype="affine" biasprm="0 -20 -12"/>


At the foot, add joint and put stiffness -> passive forces
IRON DENSITY: 7874
EARTH DENSITY: 3000
GEAR: 225

-->